Workbook

Sheet Read Me
A1: Step / rule | B1: Details
A2: 1. Enter your availability | B2: Change the green inputs in Settings: start date, total hours per study day, study/rest pattern, contingency, usable fraction, and allocations.
A3: 2. Choose scope | B3: Schedule contains 48 editable modules covering all 94 original FDE topics, explicit foundational bridges, practice, and capstone work. Optional alternatives start excluded. The 5,044 reference subtopics are not all mandatory.
A4: 3. Calibrate estimates | B4: Hours are author-created planning assumptions, not measured course durations. Run a diagnostic, then edit estimates and progress. Keep essential prerequisites included; use 100% complete for demonstrated prior knowledge.
A5: 4. Read the forecast | B5: Dashboard summarizes remaining effort, completion, and finish. Schedule has module dates. Weekly Timeline shows a fixed 104-week window; forecasts beyond it still have full dates.
A6: 5. Parallel does not mean extra capacity | B6: Core, Practice, and Delivery share the same usable hours. Each lane is ordered sequentially; explicit prerequisites can delay another lane. Unused lane time is not automatically reallocated.
A7: 6. Capacity model | B7: Remaining hours = estimate x (1-completion) x (1+contingency). Lane capacity = daily hours x usable fraction x lane share. Fractional study-day offsets preserve effort; calendar dates are rounded to study days.
A8: 7. Dependencies and blocks | B8: Prerequisite IDs must exist earlier in Schedule and be included. Later references, missing IDs, disabled required tasks, invalid inputs, or zero capacity block the dependent work. Do not sort or reorder Schedule; use filters.
A9: 8. Completed work | B9: Completion percentages describe demonstrated task evidence. Completed or skipped tasks have no remaining hours or forecast dates. Forecasts are for the remaining plan; they are not actual completion history.
A10: 9. Practice log | B10: Record DSA, SQL, ML, or project practice and mistakes. Next review defaults to seven calendar days. Log entries do not automatically certify mastery or update Schedule percentages.
A11: 10. Holidays | B11: Add up to 100 excluded dates in Holidays. Weekend pattern is seven text digits from Monday to Sunday; 0 means available and 1 means unavailable.
A12: 11. Module granularity | B12: Topics are bundled into practical modules so related concepts and evidence can be learned together. Topic Map links each of the 94 topics to one module. Module estimates include its stated learning and exercise work; capstone modules are integrated implementation and review, not extra reading.
... A21: Main roadmap | B21: FDE Roadmap.md

Sheet Settings
A1: Setting | B1: Editable Value | C1: Meaning
A2: Start date | B2: =46318 -> 46318 | C2: Dates are forecasts for remaining work, not records of actual completion.
A3: Hours available per study day | B3: =3 -> 3 | C3: One total daily budget shared by all lanes; change this first.
A4: Weekend pattern Monday to Sunday | B4: 0000001 | C4: Seven text digits: 0=study day, 1=rest day. 0000011 means Monday-Friday.
A5: Effort contingency | B5: =0.2 -> 0.2 | C5: Extra effort applied once to each remaining task estimate.
A6: Usable time fraction | B6: =0.85 -> 0.85 | C6: Allows for interruptions; 85% of entered hours is scheduled.
A7: Core allocation | B7: =0.6 -> 0.6 | C7: Fraction of usable daily time reserved for core concepts and implementation.
A8: Practice allocation | B8: =0.2 -> 0.2 | C8: Fraction reserved for DSA, SQL, numerical ML, and revision.
A9: Delivery allocation | B9: =0.2 -> 0.2 | C9: Fraction reserved for discovery, capstone work, security, UAT, and handover.
A10: Core hours per study day | B10: =IF(B15="Ready",B3*B6*B7,0) -> 1.53 | C10: Calculated; capacity is not duplicated between lanes.
A11: Practice hours per study day | B11: =IF(B15="Ready",B3*B6*B8,0) -> 0.51 | C11: Calculated.
A12: Delivery hours per study day | B12: =IF(B15="Ready",B3*B6*B9,0) -> 0.51 | C12: Calculated.
A13: Study days per week | B13: =LEN(B4)-LEN(SUBSTITUTE(B4,"0","")) -> 6 | C13: Count of zeroes in the weekend pattern.
A14: Allocation total | B14: =SUM(B7:B9) -> 1 | C14: Must equal 100%.
A15: Input status | B15: =IF(AND(ISNUMBER(B2),B2>0,ISNUMBER(B3),B3>0,B3<=16,LEN(B4)=7,LEN(SUBSTITUTE(SUBSTITUTE(B4,"0",""),"1",""))=0,B13>0,ISNUMBER(B5),B5>=0,B5<=1,ISNUMBER(B6),B6>0,B6<=1,COUNT(B7:B9)=3,MIN(B7:B9)>=0,MAX(B7:B9)<=1,ABS(B14-1)<0.000001),"Ready","Invalid settings") -> Ready | C15: Invalid inputs suppress schedule dates rather than invent a finish date.

Sheet Dashboard
A1: Measure | B1: Calculated Result | C1: Interpretation
A2: Plan status | B2: =IF(Settings!$B$15<>"Ready","Invalid settings",IF(COUNTIF(Schedule!$M$2:$M$49,"Blocked*")+COUNTIF(Schedule!$M$2:$M$49,"Invalid*")>0,"Blocked schedule",IF(SUM(Schedule!$K$2:$K$49)=0,"No remaining work","Ready"))) -> Ready | C2: A blocked or invalid plan does not display a misleading finish date.
A3: Selected unbuffered hours | B3: =SUMIF(Schedule!$D$2:$D$49,1,Schedule!$E$2:$E$49) -> 900 | C3: Original illustrative estimates for included modules; edit estimates after an initial diagnostic.
A4: Remaining buffered hours | B4: =SUM(Schedule!$K$2:$K$49) -> 1080 | C4: Remaining estimate multiplied by contingency. Idle time from dependencies or lane reservations is not counted as study effort.
A5: Effort-weighted completion | B5: =IFERROR(SUMPRODUCT(Schedule!$D$2:$D$49,Schedule!$E$2:$E$49,Schedule!$F$2:$F$49)/SUMPRODUCT(Schedule!$D$2:$D$49,Schedule!$E$2:$E$49),0) -> 0 | C5: Estimate-weighted progress, not a guarantee of mastery.
A6: Forecast finish | B6: =IF(B2="Ready",MAX(Schedule!$Q$2:$Q$49),"") -> 46973 | C6: Forecast for the selected remaining plan. This is not a job-readiness promise.
A7: Remaining study-day span | B7: =IF(B2="Ready",ROUNDUP(MAX(Schedule!$O$2:$O$49),0),0) -> 562 | C7: Includes waiting caused by prerequisites and fixed lane allocations.
A8: Calendar-day span | B8: =IF(B2="Ready",B6-Settings!$B$2+1,0) -> 656
A9: Approximate study weeks | B9: =IF(B2="Ready",B7/Settings!$B$13,0) -> 93.666667 | C9: Study-day span divided by study days per week; holidays can increase calendar time.
A10: Core daily usable hours | B10: =Settings!B10 -> 1.53
A11: Practice daily usable hours | B11: =Settings!B11 -> 0.51
A12: Delivery daily usable hours | B12: =Settings!B12 -> 0.51
A13: Timeline display window | B13: =IF(B9>104,"Forecast exceeds 104-week chart; dates remain complete","Within 104-week chart") -> Within 104-week chart
A16: Hours/day scenario | B16: Estimated finish | C16: Same scope, progress, allocation, calendar, and contingency; change those inputs in Settings.
A17: =1 -> 1 | B17: =IF($B$2="Ready",WORKDAY.INTL(Settings!$B$2-1,MAX(1,ROUNDUP(MAX(Schedule!$O$2:$O$49)*Settings!$B$3/A17,0)),Settings!$B$4,Holidays!$A$2:$A$101),"") -> 48283
A18: =2 -> 2 | B18: =IF($B$2="Ready",WORKDAY.INTL(Settings!$B$2-1,MAX(1,ROUNDUP(MAX(Schedule!$O$2:$O$49)*Settings!$B$3/A18,0)),Settings!$B$4,Holidays!$A$2:$A$101),"") -> 47301
A19: =3 -> 3 | B19: =IF($B$2="Ready",WORKDAY.INTL(Settings!$B$2-1,MAX(1,ROUNDUP(MAX(Schedule!$O$2:$O$49)*Settings!$B$3/A19,0)),Settings!$B$4,Holidays!$A$2:$A$101),"") -> 46973
A20: =4 -> 4 | B20: =IF($B$2="Ready",WORKDAY.INTL(Settings!$B$2-1,MAX(1,ROUNDUP(MAX(Schedule!$O$2:$O$49)*Settings!$B$3/A20,0)),Settings!$B$4,Holidays!$A$2:$A$101),"") -> 46809
A21: =6 -> 6 | B21: =IF($B$2="Ready",WORKDAY.INTL(Settings!$B$2-1,MAX(1,ROUNDUP(MAX(Schedule!$O$2:$O$49)*Settings!$B$3/A21,0)),Settings!$B$4,Holidays!$A$2:$A$101),"") -> 46645

Sheet Schedule
A1: ID | B1: Learning module | C1: Lane | D1: Include 1/0 | E1: Estimate hours | F1: Complete % | G1: Prerequisite 1 | H1: Prerequisite 2 | I1: Prerequisite 3 | J1: Prerequisite 4 | K1: Remaining buffered hours | L1: Lane hours/day | M1: Status | N1: Start study-day offset | O1: Finish study-day offset | P1: Planned start | Q1: Planned finish | R1: Study-day duration | S1: Completion evidence | T1: Practice / reference URL
A2: F01 | B2: FDE role and delivery orientation | C2: Core | D2: =1 -> 1 | E2: =4 -> 4 | F2: =0 -> 0 | K2: =IF(D2=0,0,IF(AND(ISNUMBER(E2),E2>=0,ISNUMBER(F2),F2>=0,F2<=1),E2*(1-F2)*(1+Settings!$B$5),0)) -> 4.8 | L2: =IFERROR(INDEX(Settings!$B$10:$B$12,MATCH(C2,{"Core","Practice","Delivery"},0)),0) -> 1.53 | M2: =IF(D2=0,"Skipped",IF(Settings!$B$15<>"Ready","Invalid settings",IF(OR(D2<>1,COUNTIF($A$2:$A$49,A2)<>1,NOT(ISNUMBER(E2)),E2<0,NOT(ISNUMBER(F2)),F2<0,F2>1),"Invalid input",IF(F2=1,"Complete",IF(OR(L2<=0,FALSE,G2<>"",H2<>"",I2<>"",J2<>""),"Blocked","Planned"))))) -> Planned | N2: =IF(M2="Skipped",0,IF(OR(M2="Planned",M2="Complete"),MAX(0,0,0,0,0),"")) -> 0 | O2: =IF(M2="Skipped",N2,IF(OR(M2="Planned",M2="Complete"),N2+IF(K2=0,0,K2/L2),"")) -> 3.1372549 | P2: =IF(AND(M2="Planned",K2>0),WORKDAY.INTL(Settings!$B$2-1,INT(N2+0.000000001)+1,Settings!$B$4,Holidays!$A$2:$A$101),"") -> 46318 | Q2: =IF(AND(M2="Planned",K2>0),WORKDAY.INTL(Settings!$B$2-1,MAX(1,ROUNDUP(O2-0.000000001,0)),Settings!$B$4,Holidays!$A$2:$A$101),"") -> 46322 | R2: =IF(OR(M2="Planned",M2="Complete"),O2-N2,0) -> 3.1372549 | S2: Explain customer ownership, role boundaries, and a reason to stop an engagement. | T2: https://roadmap.sh/forward-deployed-engineer
A3: F02 | B3: Primary language: Python | C3: Core | D3: =1 -> 1 | E3: =32 -> 32 | F3: =0 -> 0 | G3: F01 | K3: =IF(D3=0,0,IF(AND(ISNUMBER(E3),E3>=0,ISNUMBER(F3),F3>=0,F3<=1),E3*(1-F3)*(1+Settings!$B$5),0)) -> 38.4 | L3: =IFERROR(INDEX(Settings!$B$10:$B$12,MATCH(C3,{"Core","Practice","Delivery"},0)),0) -> 1.53 | M3: =IF(D3=0,"Skipped",IF(Settings!$B$15<>"Ready","Invalid settings",IF(OR(D3<>1,COUNTIF($A$2:$A$49,A3)<>1,NOT(ISNUMBER(E3)),E3<0,NOT(ISNUMBER(F3)),F3<0,F3>1),"Invalid input",IF(F3=1,"Complete",IF(OR(L3<=0,COUNTIFS($C$2:C2,C3,$M$2:M2,"Blocked*")+COUNTIFS($C$2:C2,C3,$M$2:M2,"Invalid*")>0,AND(G3<>"",OR(IFERROR(INDEX($D$2:$D$2,MATCH(G3,$A$2:$A$2,0)),0)<>1,IFERROR(INDEX($M$2:$M$2,MATCH(G3,$A$2:$A$2,0)),"Blocked")="Blocked",LEFT(IFERROR(INDEX($M$2:$M$2,MATCH(G3,$A$2:$A$2,0)),"Invalid"),7)="Invalid")),AND(H3<>"",OR(IFERROR(INDEX($D$2:$D$2,MATCH(H3,$A$2:$A$2,0)),0)<>1,IFERROR(INDEX($M$2:$M$2,MATCH(H3,$A$2:$A$2,0)),"Blocked")="Blocked",LEFT(IFERROR(INDEX($M$2:$M$2,MATCH(H3,$A$2:$A$2,0)),"Invalid"),7)="Invalid")),AND(I3<>"",OR(IFERROR(INDEX($D$2:$D$2,MATCH(I3,$A$2:$A$2,0)),0)<>1,IFERROR(INDEX($M$2:$M$2,MATCH(I3,$A$2:$A$2,0)),"Blocked")="Blocked",LEFT(IFERROR(INDEX($M$2:$M$2,MATCH(I3,$A$2:$A$2,0)),"Invalid"),7)="Invalid")),AND(J3<>"",OR(IFERROR(INDEX($D$2:$D$2,MATCH(J3,$A$2:$A$2,0)),0)<>1,IFERROR(INDEX($M$2:$M$2,MATCH(J3,$A$2:$A$2,0)),"Blocked")="Blocked",LEFT(IFERROR(INDEX($M$2:$M$2,MATCH(J3,$A$2:$A$2,0)),"Invalid"),7)="Invalid"))),"Blocked","Planned"))))) -> Planned | N3: =IF(M3="Skipped",O2,IF(OR(M3="Planned",M3="Complete"),MAX(O2,IF(G3="",0,IFERROR(INDEX($O$2:$O$2,MATCH(G3,$A$2:$A$2,0)),0)),IF(H3="",0,IFERROR(INDEX($O$2:$O$2,MATCH(H3,$A$2:$A$2,0)),0)),IF(I3="",0,IFERROR(INDEX($O$2:$O$2,MATCH(I3,$A$2:$A$2,0)),0)),IF(J3="",0,IFERROR(INDEX($O$2:$O$2,MATCH(J3,$A$2:$A$2,0)),0))),"")) -> 3.1372549 | O3: =IF(M3="Skipped",N3,IF(OR(M3="Planned",M3="Complete"),N3+IF(K3=0,0,K3/L3),"")) -> 28.235294 | P3: =IF(AND(M3="Planned",K3>0),WORKDAY.INTL(Settings!$B$2-1,INT(N3+0.000000001)+1,Settings!$B$4,Holidays!$A$2:$A$101),"") -> 46322 | Q3: =IF(AND(M3="Planned",K3>0),WORKDAY.INTL(Settings!$B$2-1,MAX(1,ROUNDUP(O3-0.000000001,0)),Settings!$B$4,Holidays!$A$2:$A$101),"") -> 46351 | R3: =IF(OR(M3="Planned",M3="Complete"),O3-N3,0) -> 25.098039 | S3: Run a tested ingestion command in a fresh environment. | T3: https://www.deep-ml.com/paths
A4: F03 | B4: Git Linux and debugging foundations | C4: Core | D4: =1 -> 1 | E4: =18 -> 18 | F4: =0 -> 0 | G4: F02 | K4: =IF(D4=0,0,IF(AND(ISNUMBER(E4),E4>=0,ISNUMBER(F4),F4>=0,F4<=1),E4*(1-F4)*(1+Settings!$B$5),0)) -> 21.6 | L4: =IFERROR(INDEX(Settings!$B$10:$B$12,MATCH(C4,{"Core","Practice","Delivery"},0)),0) -> 1.53 | M4: =IF(D4=0,"Skipped",IF(Settings!$B$15<>"Ready","Invalid settings",IF(OR(D4<>1,COUNTIF($A$2:$A$49,A4)<>1,NOT(ISNUMBER(E4)),E4<0,NOT(ISNUMBER(F4)),F4<0,F4>1),"Invalid input",IF(F4=1,"Complete",IF(OR(L4<=0,COUNTIFS($C$2:C3,C4,$M$2:M3,"Blocked*")+COUNTIFS($C$2:C3,C4,$M$2:M3,"Invalid*")>0,AND(G4<>"",OR(IFERROR(INDEX($D$2:$D$3,MATCH(G4,$A$2:$A$3,0)),0)<>1,IFERROR(INDEX($M$2:$M$3,MATCH(G4,$A$2:$A$3,0)),"Blocked")="Blocked",LEFT(IFERROR(INDEX($M$2:$M$3,MATCH(G4,$A$2:$A$3,0)),"Invalid"),7)="Invalid")),AND(H4<>"",OR(IFERROR(INDEX($D$2:$D$3,MATCH(H4,$A$2:$A$3,0)),0)<>1,IFERROR(INDEX($M$2:$M$3,MATCH(H4,$A$2:$A$3,0)),"Blocked")="Blocked",LEFT(IFERROR(INDEX($M$2:$M$3,MATCH(H4,$A$2:$A$3,0)),"Invalid"),7)="Invalid")),AND(I4<>"",OR(IFERROR(INDEX($D$2:$D$3,MATCH(I4,$A$2:$A$3,0)),0)<>1,IFERROR(INDEX($M$2:$M$3,MATCH(I4,$A$2:$A$3,0)),"Blocked")="Blocked",LEFT(IFERROR(INDEX($M$2:$M$3,MATCH(I4,$A$2:$A$3,0)),"Invalid"),7)="Invalid")),AND(J4<>"",OR(IFERROR(INDEX($D$2:$D$3,MATCH(J4,$A$2:$A$3,0)),0)<>1,IFERROR(INDEX($M$2:$M$3,MATCH(J4,$A$2:$A$3,0)),"Blocked")="Blocked",LEFT(IFERROR(INDEX($M$2:$M$3,MATCH(J4,$A$2:$A$3,0)),"Invalid"),7)="Invalid"))),"Blocked","Planned"))))) -> Planned | N4: =IF(M4="Skipped",O3,IF(OR(M4="Planned",M4="Complete"),MAX(O3,IF(G4="",0,IFERROR(INDEX($O$2:$O$3,MATCH(G4,$A$2:$A$3,0)),0)),IF(H4="",0,IFERROR(INDEX($O$2:$O$3,MATCH(H4,$A$2:$A$3,0)),0)),IF(I4="",0,IFERROR(INDEX($O$2:$O$3,MATCH(I4,$A$2:$A$3,0)),0)),IF(J4="",0,IFERROR(INDEX($O$2:$O$3,MATCH(J4,$A$2:$A$3,0)),0))),"")) -> 28.235294 | O4: =IF(M4="Skipped",N4,IF(OR(M4="Planned",M4="Complete"),N4+IF(K4=0,0,K4/L4),"")) -> 42.352941 | P4: =IF(AND(M4="Planned",K4>0),WORKDAY.INTL(Settings!$B$2-1,INT(N4+0.000000001)+1,Settings!$B$4,Holidays!$A$2:$A$101),"") -> 46351 | Q4: =IF(AND(M4="Planned",K4>0),WORKDAY.INTL(Settings!$B$2-1,MAX(1,ROUNDUP(O4-0.000000001,0)),Settings!$B$4,Holidays!$A$2:$A$101),"") -> 46367 | R4: =IF(OR(M4="Planned",M4="Complete"),O4-N4,0) -> 14.117647 | S4: Diagnose a failed service and deliver a reviewable change. | T4: https://roadmap.sh/git-github
A5: F04 | B5: Testing and reproducible project bridge | C5: Core | D5: =1 -> 1 | E5: =20 -> 20 | F5: =0 -> 0 | G5: F03 | K5: =IF(D5=0,0,IF(AND(ISNUMBER(E5),E5>=0,ISNUMBER(F5),F5>=0,F5<=1),E5*(1-F5)*(1+Settings!$B$5),0)) -> 24 | L5: =IFERROR(INDEX(Settings!$B$10:$B$12,MATCH(C5,{"Core","Practice","Delivery"},0)),0) -> 1.53 | M5: =IF(D5=0,"Skipped",IF(Settings!$B$15<>"Ready","Invalid settings",IF(OR(D5<>1,COUNTIF($A$2:$A$49,A5)<>1,NOT(ISNUMBER(E5)),E5<0,NOT(ISNUMBER(F5)),F5<0,F5>1),"Invalid input",IF(F5=1,"Complete",IF(OR(L5<=0,COUNTIFS($C$2:C4,C5,$M$2:M4,"Blocked*")+COUNTIFS($C$2:C4,C5,$M$2:M4,"Invalid*")>0,AND(G5<>"",OR(IFERROR(INDEX($D$2:$D$4,MATCH(G5,$A$2:$A$4,0)),0)<>1,IFERROR(INDEX($M$2:$M$4,MATCH(G5,$A$2:$A$4,0)),"Blocked")="Blocked",LEFT(IFERROR(INDEX($M$2:$M$4,MATCH(G5,$A$2:$A$4,0)),"Invalid"),7)="Invalid")),AND(H5<>"",OR(IFERROR(INDEX($D$2:$D$4,MATCH(H5,$A$2:$A$4,0)),0)<>1,IFERROR(INDEX($M$2:$M$4,MATCH(H5,$A$2:$A$4,0)),"Blocked")="Blocked",LEFT(IFERROR(INDEX($M$2:$M$4,MATCH(H5,$A$2:$A$4,0)),"Invalid"),7)="Invalid")),AND(I5<>"",OR(IFERROR(INDEX($D$2:$D$4,MATCH(I5,$A$2:$A$4,0)),0)<>1,IFERROR(INDEX($M$2:$M$4,MATCH(I5,$A$2:$A$4,0)),"Blocked")="Blocked",LEFT(IFERROR(INDEX($M$2:$M$4,MATCH(I5,$A$2:$A$4,0)),"Invalid"),7)="Invalid")),AND(J5<>"",OR(IFERROR(INDEX($D$2:$D$4,MATCH(J5,$A$2:$A$4,0)),0)<>1,IFERROR(INDEX($M$2:$M$4,MATCH(J5,$A$2:$A$4,0)),"Blocked")="Blocked",LEFT(IFERROR(INDEX($M$2:$M$4,MATCH(J5,$A$2:$A$4,0)),"Invalid"),7)="Invalid"))),"Blocked","Planned"))))) -> Planned | N5: =IF(M5="Skipped",O4,IF(OR(M5="Planned",M5="Complete"),MAX(O4,IF(G5="",0,IFERROR(INDEX($O$2:$O$4,MATCH(G5,$A$2:$A$4,0)),0)),IF(H5="",0,IFERROR(INDEX($O$2:$O$4,MATCH(H5,$A$2:$A$4,0)),0)),IF(I5="",0,IFERROR(INDEX($O$2:$O$4,MATCH(I5,$A$2:$A$4,0)),0)),IF(J5="",0,IFERROR(INDEX($O$2:$O$4,MATCH(J5,$A$2:$A$4,0)),0))),"")) -> 42.352941 | O5: =IF(M5="Skipped",N5,IF(OR(M5="Planned",M5="Complete"),N5+IF(K5=0,0,K5/L5),"")) -> 58.039216 | P5: =IF(AND(M5="Planned",K5>0),WORKDAY.INTL(Settings!$B$2-1,INT(N5+0.000000001)+1,Settings!$B$4,Holidays!$A$2:$A$101),"") -> 46367 | Q5: =IF(AND(M5="Planned",K5>0),WORKDAY.INTL(Settings!$B$2-1,MAX(1,ROUNDUP(O5-0.000000001,0)),Settings!$B$4,Holidays!$A$2:$A$101),"") -> 46386 | R5: =IF(OR(M5="Planned",M5="Complete"),O5-N5,0) -> 15.686275 | S5: Write unit, integration, and contract tests with fixtures and a CI check. | T5: https://abseil.io/resources/swe-book
A6: F05 | B6: HTTP backend and API contracts | C6: Core | D6: =1 -> 1 | E6: =30 -> 30 | F6: =0 -> 0 | G6: F04 | K6: =IF(D6=0,0,IF(AND(ISNUMBER(E6),E6>=0,ISNUMBER(F6),F6>=0,F6<=1),E6*(1-F6)*(1+Settings!$B$5),0)) -> 36 | L6: =IFERROR(INDEX(Settings!$B$10:$B$12,MATCH(C6,{"Core","Practice","Delivery"},0)),0) -> 1.53 | M6: =IF(D6=0,"Skipped",IF(Settings!$B$15<>"Ready","Invalid settings",IF(OR(D6<>1,COUNTIF($A$2:$A$49,A6)<>1,NOT(ISNUMBER(E6)),E6<0,NOT(ISNUMBER(F6)),F6<0,F6>1),"Invalid input",IF(F6=1,"Complete",IF(OR(L6<=0,COUNTIFS($C$2:C5,C6,$M$2:M5,"Blocked*")+COUNTIFS($C$2:C5,C6,$M$2:M5,"Invalid*")>0,AND(G6<>"",OR(IFERROR(INDEX($D$2:$D$5,MATCH(G6,$A$2:$A$5,0)),0)<>1,IFERROR(INDEX($M$2:$M$5,MATCH(G6,$A$2:$A$5,0)),"Blocked")="Blocked",LEFT(IFERROR(INDEX($M$2:$M$5,MATCH(G6,$A$2:$A$5,0)),"Invalid"),7)="Invalid")),AND(H6<>"",OR(IFERROR(INDEX($D$2:$D$5,MATCH(H6,$A$2:$A$5,0)),0)<>1,IFERROR(INDEX($M$2:$M$5,MATCH(H6,$A$2:$A$5,0)),"Blocked")="Blocked",LEFT(IFERROR(INDEX($M$2:$M$5,MATCH(H6,$A$2:$A$5,0)),"Invalid"),7)="Invalid")),AND(I6<>"",OR(IFERROR(INDEX($D$2:$D$5,MATCH(I6,$A$2:$A$5,0)),0)<>1,IFERROR(INDEX($M$2:$M$5,MATCH(I6,$A$2:$A$5,0)),"Blocked")="Blocked",LEFT(IFERROR(INDEX($M$2:$M$5,MATCH(I6,$A$2:$A$5,0)),"Invalid"),7)="Invalid")),AND(J6<>"",OR(IFERROR(INDEX($D$2:$D$5,MATCH(J6,$A$2:$A$5,0)),0)<>1,IFERROR(INDEX($M$2:$M$5,MATCH(J6,$A$2:$A$5,0)),"Blocked")="Blocked",LEFT(IFERROR(INDEX($M$2:$M$5,MATCH(J6,$A$2:$A$5,0)),"Invalid"),7)="Invalid"))),"Blocked","Planned"))))) -> Planned | N6: =IF(M6="Skipped",O5,IF(OR(M6="Planned",M6="Complete"),MAX(O5,IF(G6="",0,IFERROR(INDEX($O$2:$O$5,MATCH(G6,$A$2:$A$5,0)),0)),IF(H6="",0,IFERROR(INDEX($O$2:$O$5,MATCH(H6,$A$2:$A$5,0)),0)),IF(I6="",0,IFERROR(INDEX($O$2:$O$5,MATCH(I6,$A$2:$A$5,0)),0)),IF(J6="",0,IFERROR(INDEX($O$2:$O$5,MATCH(J6,$A$2:$A$5,0)),0))),"")) -> 58.039216 | O6: =IF(M6="Skipped",N6,IF(OR(M6="Planned",M6="Complete"),N6+IF(K6=0,0,K6/L6),"")) -> 81.568627 | P6: =IF(AND(M6="Planned",K6>0),WORKDAY.INTL(Settings!$B$2-1,INT(N6+0.000000001)+1,Settings!$B$4,Holidays!$A$2:$A$101),"") -> 46386 | Q6: =IF(AND(M6="Planned",K6>0),WORKDAY.INTL(Settings!$B$2-1,MAX(1,ROUNDUP(O6-0.000000001,0)),Settings!$B$4,Holidays!$A$2:$A$101),"") -> 46413 | R6: =IF(OR(M6="Planned",M6="Complete"),O6-N6,0) -> 23.529412 | S6: Build a validated API and durable job workflow with explicit errors. | T6: https://roadmap.sh/backend
A7: F06 | B7: SQL relational modeling and PostgreSQL | C7: Core | D7: =1 -> 1 | E7: =32 -> 32 | F7: =0 -> 0 | G7: F03 | K7: =IF(D7=0,0,IF(AND(ISNUMBER(E7),E7>=0,ISNUMBER(F7),F7>=0,F7<=1),E7*(1-F7)*(1+Settings!$B$5),0)) -> 38.4 | L7: =IFERROR(INDEX(Settings!$B$10:$B$12,MATCH(C7,{"Core","Practice","Delivery"},0)),0) -> 1.53 | M7: =IF(D7=0,"Skipped",IF(Settings!$B$15<>"Ready","Invalid settings",IF(OR(D7<>1,COUNTIF($A$2:$A$49,A7)<>1,NOT(ISNUMBER(E7)),E7<0,NOT(ISNUMBER(F7)),F7<0,F7>1),"Invalid input",IF(F7=1,"Complete",IF(OR(L7<=0,COUNTIFS($C$2:C6,C7,$M$2:M6,"Blocked*")+COUNTIFS($C$2:C6,C7,$M$2:M6,"Invalid*")>0,AND(G7<>"",OR(IFERROR(INDEX($D$2:$D$6,MATCH(G7,$A$2:$A$6,0)),0)<>1,IFERROR(INDEX($M$2:$M$6,MATCH(G7,$A$2:$A$6,0)),"Blocked")="Blocked",LEFT(IFERROR(INDEX($M$2:$M$6,MATCH(G7,$A$2:$A$6,0)),"Invalid"),7)="Invalid")),AND(H7<>"",OR(IFERROR(INDEX($D$2:$D$6,MATCH(H7,$A$2:$A$6,0)),0)<>1,IFERROR(INDEX($M$2:$M$6,MATCH(H7,$A$2:$A$6,0)),"Blocked")="Blocked",LEFT(IFERROR(INDEX($M$2:$M$6,MATCH(H7,$A$2:$A$6,0)),"Invalid"),7)="Invalid")),AND(I7<>"",OR(IFERROR(INDEX($D$2:$D$6,MATCH(I7,$A$2:$A$6,0)),0)<>1,IFERROR(INDEX($M$2:$M$6,MATCH(I7,$A$2:$A$6,0)),"Blocked")="Blocked",LEFT(IFERROR(INDEX($M$2:$M$6,MATCH(I7,$A$2:$A$6,0)),"Invalid"),7)="Invalid")),AND(J7<>"",OR(IFERROR(INDEX($D$2:$D$6,MATCH(J7,$A$2:$A$6,0)),0)<>1,IFERROR(INDEX($M$2:$M$6,MATCH(J7,$A$2:$A$6,0)),"Blocked")="Blocked",LEFT(IFERROR(INDEX($M$2:$M$6,MATCH(J7,$A$2:$A$6,0)),"Invalid"),7)="Invalid"))),"Blocked","Planned"))))) -> Planned | N7: =IF(M7="Skipped",O6,IF(OR(M7="Planned",M7="Complete"),MAX(O6,IF(G7="",0,IFERROR(INDEX($O$2:$O$6,MATCH(G7,$A$2:$A$6,0)),0)),IF(H7="",0,IFERROR(INDEX($O$2:$O$6,MATCH(H7,$A$2:$A$6,0)),0)),IF(I7="",0,IFERROR(INDEX($O$2:$O$6,MATCH(I7,$A$2:$A$6,0)),0)),IF(J7="",0,IFERROR(INDEX($O$2:$O$6,MATCH(J7,$A$2:$A$6,0)),0))),"")) -> 81.568627 | O7: =IF(M7="Skipped",N7,IF(OR(M7="Planned",M7="Complete"),N7+IF(K7=0,0,K7/L7),"")) -> 106.66667 | P7: =IF(AND(M7="Planned",K7>0),WORKDAY.INTL(Settings!$B$2-1,INT(N7+0.000000001)+1,Settings!$B$4,Holidays!$A$2:$A$101),"") -> 46413 | Q7: =IF(AND(M7="Planned",K7>0),WORKDAY.INTL(Settings!$B$2-1,MAX(1,ROUNDUP(O7-0.000000001,0)),Settings!$B$4,Holidays!$A$2:$A$101),"") -> 46442 | R7: =IF(OR(M7="Planned",M7="Complete"),O7-N7,0) -> 25.098039 | S7: Reconcile joins, constrain data, inspect a plan, and restore a test backup. | T7: https://datalemur.com/
A8: F07 | B8: One usable frontend stack | C8: Core | D8: =1 -> 1 | E8: =32 -> 32 | F8: =0 -> 0 | G8: F05 | K8: =IF(D8=0,0,IF(AND(ISNUMBER(E8),E8>=0,ISNUMBER(F8),F8>=0,F8<=1),E8*(1-F8)*(1+Settings!$B$5),0)) -> 38.4 | L8: =IFERROR(INDEX(Settings!$B$10:$B$12,MATCH(C8,{"Core","Practice","Delivery"},0)),0) -> 1.53 | M8: =IF(D8=0,"Skipped",IF(Settings!$B$15<>"Ready","Invalid settings",IF(OR(D8<>1,COUNTIF($A$2:$A$49,A8)<>1,NOT(ISNUMBER(E8)),E8<0,NOT(ISNUMBER(F8)),F8<0,F8>1),"Invalid input",IF(F8=1,"Complete",IF(OR(L8<=0,COUNTIFS($C$2:C7,C8,$M$2:M7,"Blocked*")+COUNTIFS($C$2:C7,C8,$M$2:M7,"Invalid*")>0,AND(G8<>"",OR(IFERROR(INDEX($D$2:$D$7,MATCH(G8,$A$2:$A$7,0)),0)<>1,IFERROR(INDEX($M$2:$M$7,MATCH(G8,$A$2:$A$7,0)),"Blocked")="Blocked",LEFT(IFERROR(INDEX($M$2:$M$7,MATCH(G8,$A$2:$A$7,0)),"Invalid"),7)="Invalid")),AND(H8<>"",OR(IFERROR(INDEX($D$2:$D$7,MATCH(H8,$A$2:$A$7,0)),0)<>1,IFERROR(INDEX($M$2:$M$7,MATCH(H8,$A$2:$A$7,0)),"Blocked")="Blocked",LEFT(IFERROR(INDEX($M$2:$M$7,MATCH(H8,$A$2:$A$7,0)),"Invalid"),7)="Invalid")),AND(I8<>"",OR(IFERROR(INDEX($D$2:$D$7,MATCH(I8,$A$2:$A$7,0)),0)<>1,IFERROR(INDEX($M$2:$M$7,MATCH(I8,$A$2:$A$7,0)),"Blocked")="Blocked",LEFT(IFERROR(INDEX($M$2:$M$7,MATCH(I8,$A$2:$A$7,0)),"Invalid"),7)="Invalid")),AND(J8<>"",OR(IFERROR(INDEX($D$2:$D$7,MATCH(J8,$A$2:$A$7,0)),0)<>1,IFERROR(INDEX($M$2:$M$7,MATCH(J8,$A$2:$A$7,0)),"Blocked")="Blocked",LEFT(IFERROR(INDEX($M$2:$M$7,MATCH(J8,$A$2:$A$7,0)),"Invalid"),7)="Invalid"))),"Blocked","Planned"))))) -> Planned | N8: =IF(M8="Skipped",O7,IF(OR(M8="Planned",M8="Complete"),MAX(O7,IF(G8="",0,IFERROR(INDEX($O$2:$O$7,MATCH(G8,$A$2:$A$7,0)),0)),IF(H8="",0,IFERROR(INDEX($O$2:$O$7,MATCH(H8,$A$2:$A$7,0)),0)),IF(I8="",0,IFERROR(INDEX($O$2:$O$7,MATCH(I8,$A$2:$A$7,0)),0)),IF(J8="",0,IFERROR(INDEX($O$2:$O$7,MATCH(J8,$A$2:$A$7,0)),0))),"")) -> 106.66667 | O8: =IF(M8="Skipped",N8,IF(OR(M8="Planned",M8="Complete"),N8+IF(K8=0,0,K8/L8),"")) -> 131.76471 | P8: =IF(AND(M8="Planned",K8>0),WORKDAY.INTL(Settings!$B$2-1,INT(N8+0.000000001)+1,Settings!$B$4,Holidays!$A$2:$A$101),"") -> 46442 | Q8: =IF(AND(M8="Planned",K8>0),WORKDAY.INTL(Settings!$B$2-1,MAX(1,ROUNDUP(O8-0.000000001,0)),Settings!$B$4,Holidays!$A$2:$A$101),"") -> 46471 | R8: =IF(OR(M8="Planned",M8="Complete"),O8-N8,0) -> 25.098039 | S8: Complete an accessible review flow including failure and loading states. | T8: https://roadmap.sh/frontend
A9: F08 | B9: Data lifecycle pipelines and quality | C9: Core | D9: =1 -> 1 | E9: =28 -> 28 | F9: =0 -> 0 | G9: F06 | H9: F04 | K9: =IF(D9=0,0,IF(AND(ISNUMBER(E9),E9>=0,ISNUMBER(F9),F9>=0,F9<=1),E9*(1-F9)*(1+Settings!$B$5),0)) -> 33.6 | L9: =IFERROR(INDEX(Settings!$B$10:$B$12,MATCH(C9,{"Core","Practice","Delivery"},0)),0) -> 1.53 | M9: =IF(D9=0,"Skipped",IF(Settings!$B$15<>"Ready","Invalid settings",IF(OR(D9<>1,COUNTIF($A$2:$A$49,A9)<>1,NOT(ISNUMBER(E9)),E9<0,NOT(ISNUMBER(F9)),F9<0,F9>1),"Invalid input",IF(F9=1,"Complete",IF(OR(L9<=0,COUNTIFS($C$2:C8,C9,$M$2:M8,"Blocked*")+COUNTIFS($C$2:C8,C9,$M$2:M8,"Invalid*")>0,AND(G9<>"",OR(IFERROR(INDEX($D$2:$D$8,MATCH(G9,$A$2:$A$8,0)),0)<>1,IFERROR(INDEX($M$2:$M$8,MATCH(G9,$A$2:$A$8,0)),"Blocked")="Blocked",LEFT(IFERROR(INDEX($M$2:$M$8,MATCH(G9,$A$2:$A$8,0)),"Invalid"),7)="Invalid")),AND(H9<>"",OR(IFERROR(INDEX($D$2:$D$8,MATCH(H9,$A$2:$A$8,0)),0)<>1,IFERROR(INDEX($M$2:$M$8,MATCH(H9,$A$2:$A$8,0)),"Blocked")="Blocked",LEFT(IFERROR(INDEX($M$2:$M$8,MATCH(H9,$A$2:$A$8,0)),"Invalid"),7)="Invalid")),AND(I9<>"",OR(IFERROR(INDEX($D$2:$D$8,MATCH(I9,$A$2:$A$8,0)),0)<>1,IFERROR(INDEX($M$2:$M$8,MATCH(I9,$A$2:$A$8,0)),"Blocked")="Blocked",LEFT(IFERROR(INDEX($M$2:$M$8,MATCH(I9,$A$2:$A$8,0)),"Invalid"),7)="Invalid")),AND(J9<>"",OR(IFERROR(INDEX($D$2:$D$8,MATCH(J9,$A$2:$A$8,0)),0)<>1,IFERROR(INDEX($M$2:$M$8,MATCH(J9,$A$2:$A$8,0)),"Blocked")="Blocked",LEFT(IFERROR(INDEX($M$2:$M$8,MATCH(J9,$A$2:$A$8,0)),"Invalid"),7)="Invalid"))),"Blocked","Planned"))))) -> Planned | N9: =IF(M9="Skipped",O8,IF(OR(M9="Planned",M9="Complete"),MAX(O8,IF(G9="",0,IFERROR(INDEX($O$2:$O$8,MATCH(G9,$A$2:$A$8,0)),0)),IF(H9="",0,IFERROR(INDEX($O$2:$O$8,MATCH(H9,$A$2:$A$8,0)),0)),IF(I9="",0,IFERROR(INDEX($O$2:$O$8,MATCH(I9,$A$2:$A$8,0)),0)),IF(J9="",0,IFERROR(INDEX($O$2:$O$8,MATCH(J9,$A$2:$A$8,0)),0))),"")) -> 131.76471 | O9: =IF(M9="Skipped",N9,IF(OR(M9="Planned",M9="Complete"),N9+IF(K9=0,0,K9/L9),"")) -> 153.72549 | P9: =IF(AND(M9="Planned",K9>0),WORKDAY.INTL(Settings!$B$2-1,INT(N9+0.000000001)+1,Settings!$B$4,Holidays!$A$2:$A$101),"") -> 46471 | Q9: =IF(AND(M9="Planned",K9>0),WORKDAY.INTL(Settings!$B$2-1,MAX(1,ROUNDUP(O9-0.000000001,0)),Settings!$B$4,Holidays!$A$2:$A$101),"") -> 46497 | R9: =IF(OR(M9="Planned",M9="Complete"),O9-N9,0) -> 21.960784 | S9: Trace a serving record to source and replay data without duplication. | T9: https://roadmap.sh/data-engineer
A10: B01 | B10: Linear algebra and numerical reasoning bridge | C10: Core | D10: =1 -> 1 | E10: =18 -> 18 | F10: =0 -> 0 | G10: F02 | K10: =IF(D10=0,0,IF(AND(ISNUMBER(E10),E10>=0,ISNUMBER(F10),F10>=0,F10<=1),E10*(1-F10)*(1+Settings!$B$5),0)) -> 21.6 | L10: =IFERROR(INDEX(Settings!$B$10:$B$12,MATCH(C10,{"Core","Practice","Delivery"},0)),0) -> 1.53 | M10: =IF(D10=0,"Skipped",IF(Settings!$B$15<>"Ready","Invalid settings",IF(OR(D10<>1,COUNTIF($A$2:$A$49,A10)<>1,NOT(ISNUMBER(E10)),E10<0,NOT(ISNUMBER(F10)),F10<0,F10>1),"Invalid input",IF(F10=1,"Complete",IF(OR(L10<=0,COUNTIFS($C$2:C9,C10,$M$2:M9,"Blocked*")+COUNTIFS($C$2:C9,C10,$M$2:M9,"Invalid*")>0,AND(G10<>"",OR(IFERROR(INDEX($D$2:$D$9,MATCH(G10,$A$2:$A$9,0)),0)<>1,IFERROR(INDEX($M$2:$M$9,MATCH(G10,$A$2:$A$9,0)),"Blocked")="Blocked",LEFT(IFERROR(INDEX($M$2:$M$9,MATCH(G10,$A$2:$A$9,0)),"Invalid"),7)="Invalid")),AND(H10<>"",OR(IFERROR(INDEX($D$2:$D$9,MATCH(H10,$A$2:$A$9,0)),0)<>1,IFERROR(INDEX($M$2:$M$9,MATCH(H10,$A$2:$A$9,0)),"Blocked")="Blocked",LEFT(IFERROR(INDEX($M$2:$M$9,MATCH(H10,$A$2:$A$9,0)),"Invalid"),7)="Invalid")),AND(I10<>"",OR(IFERROR(INDEX($D$2:$D$9,MATCH(I10,$A$2:$A$9,0)),0)<>1,IFERROR(INDEX($M$2:$M$9,MATCH(I10,$A$2:$A$9,0)),"Blocked")="Blocked",LEFT(IFERROR(INDEX($M$2:$M$9,MATCH(I10,$A$2:$A$9,0)),"Invalid"),7)="Invalid")),AND(J10<>"",OR(IFERROR(INDEX($D$2:$D$9,MATCH(J10,$A$2:$A$9,0)),0)<>1,IFERROR(INDEX($M$2:$M$9,MATCH(J10,$A$2:$A$9,0)),"Blocked")="Blocked",LEFT(IFERROR(INDEX($M$2:$M$9,MATCH(J10,$A$2:$A$9,0)),"Invalid"),7)="Invalid"))),"Blocked","Planned"))))) -> Planned | N10: =IF(M10="Skipped",O9,IF(OR(M10="Planned",M10="Complete"),MAX(O9,IF(G10="",0,IFERROR(INDEX($O$2:$O$9,MATCH(G10,$A$2:$A$9,0)),0)),IF(H10="",0,IFERROR(INDEX($O$2:$O$9,MATCH(H10,$A$2:$A$9,0)),0)),IF(I10="",0,IFERROR(INDEX($O$2:$O$9,MATCH(I10,$A$2:$A$9,0)),0)),IF(J10="",0,IFERROR(INDEX($O$2:$O$9,MATCH(J10,$A$2:$A$9,0)),0))),"")) -> 153.72549 | O10: =IF(M10="Skipped",N10,IF(OR(M10="Planned",M10="Complete"),N10+IF(K10=0,0,K10/L10),"")) -> 167.84314 | P10: =IF(AND(M10="Planned",K10>0),WORKDAY.INTL(Settings!$B$2-1,INT(N10+0.000000001)+1,Settings!$B$4,Holidays!$A$2:$A$101),"") -> 46497 | Q10: =IF(AND(M10="Planned",K10>0),WORKDAY.INTL(Settings!$B$2-1,MAX(1,ROUNDUP(O10-0.000000001,0)),Settings!$B$4,Holidays!$A$2:$A$101),"") -> 46513 | R10: =IF(OR(M10="Planned",M10="Complete"),O10-N10,0) -> 14.117647 | S10: Test matrix shapes, normalization, similarity, and zero-vector behavior. | T10: https://www.deep-ml.com/paths
A11: B02 | B11: Probability statistics and uncertainty bridge | C11: Core | D11: =1 -> 1 | E11: =20 -> 20 | F11: =0 -> 0 | G11: B01 | K11: =IF(D11=0,0,IF(AND(ISNUMBER(E11),E11>=0,ISNUMBER(F11),F11>=0,F11<=1),E11*(1-F11)*(1+Settings!$B$5),0)) -> 24 | L11: =IFERROR(INDEX(Settings!$B$10:$B$12,MATCH(C11,{"Core","Practice","Delivery"},0)),0) -> 1.53 | M11: =IF(D11=0,"Skipped",IF(Settings!$B$15<>"Ready","Invalid settings",IF(OR(D11<>1,COUNTIF($A$2:$A$49,A11)<>1,NOT(ISNUMBER(E11)),E11<0,NOT(ISNUMBER(F11)),F11<0,F11>1),"Invalid input",IF(F11=1,"Complete",IF(OR(L11<=0,COUNTIFS($C$2:C10,C11,$M$2:M10,"Blocked*")+COUNTIFS($C$2:C10,C11,$M$2:M10,"Invalid*")>0,AND(G11<>"",OR(IFERROR(INDEX($D$2:$D$10,MATCH(G11,$A$2:$A$10,0)),0)<>1,IFERROR(INDEX($M$2:$M$10,MATCH(G11,$A$2:$A$10,0)),"Blocked")="Blocked",LEFT(IFERROR(INDEX($M$2:$M$10,MATCH(G11,$A$2:$A$10,0)),"Invalid"),7)="Invalid")),AND(H11<>"",OR(IFERROR(INDEX($D$2:$D$10,MATCH(H11,$A$2:$A$10,0)),0)<>1,IFERROR(INDEX($M$2:$M$10,MATCH(H11,$A$2:$A$10,0)),"Blocked")="Blocked",LEFT(IFERROR(INDEX($M$2:$M$10,MATCH(H11,$A$2:$A$10,0)),"Invalid"),7)="Invalid")),AND(I11<>"",OR(IFERROR(INDEX($D$2:$D$10,MATCH(I11,$A$2:$A$10,0)),0)<>1,IFERROR(INDEX($M$2:$M$10,MATCH(I11,$A$2:$A$10,0)),"Blocked")="Blocked",LEFT(IFERROR(INDEX($M$2:$M$10,MATCH(I11,$A$2:$A$10,0)),"Invalid"),7)="Invalid")),AND(J11<>"",OR(IFERROR(INDEX($D$2:$D$10,MATCH(J11,$A$2:$A$10,0)),0)<>1,IFERROR(INDEX($M$2:$M$10,MATCH(J11,$A$2:$A$10,0)),"Blocked")="Blocked",LEFT(IFERROR(INDEX($M$2:$M$10,MATCH(J11,$A$2:$A$10,0)),"Invalid"),7)="Invalid"))),"Blocked","Planned"))))) -> Planned | N11: =IF(M11="Skipped",O10,IF(OR(M11="Planned",M11="Complete"),MAX(O10,IF(G11="",0,IFERROR(INDEX($O$2:$O$10,MATCH(G11,$A$2:$A$10,0)),0)),IF(H11="",0,IFERROR(INDEX($O$2:$O$10,MATCH(H11,$A$2:$A$10,0)),0)),IF(I11="",0,IFERROR(INDEX($O$2:$O$10,MATCH(I11,$A$2:$A$10,0)),0)),IF(J11="",0,IFERROR(INDEX($O$2:$O$10,MATCH(J11,$A$2:$A$10,0)),0))),"")) -> 167.84314 | O11: =IF(M11="Skipped",N11,IF(OR(M11="Planned",M11="Complete"),N11+IF(K11=0,0,K11/L11),"")) -> 183.52941 | P11: =IF(AND(M11="Planned",K11>0),WORKDAY.INTL(Settings!$B$2-1,INT(N11+0.000000001)+1,Settings!$B$4,Holidays!$A$2:$A$101),"") -> 46513 | Q11: =IF(AND(M11="Planned",K11>0),WORKDAY.INTL(Settings!$B$2-1,MAX(1,ROUNDUP(O11-0.000000001,0)),Settings!$B$4,Holidays!$A$2:$A$101),"") -> 46532 | R11: =IF(OR(M11="Planned",M11="Complete"),O11-N11,0) -> 15.686275 | S11: Explain base rates, sampling uncertainty, and a confidence interval. | T11: https://www.deep-ml.com/paths
A12: B03 | B12: NumPy pandas and data manipulation bridge | C12: Core | D12: =1 -> 1 | E12: =18 -> 18 | F12: =0 -> 0 | G12: B01 | H12: F06 | K12: =IF(D12=0,0,IF(AND(ISNUMBER(E12),E12>=0,ISNUMBER(F12),F12>=0,F12<=1),E12*(1-F12)*(1+Settings!$B$5),0)) -> 21.6 | L12: =IFERROR(INDEX(Settings!$B$10:$B$12,MATCH(C12,{"Core","Practice","Delivery"},0)),0) -> 1.53 | M12: =IF(D12=0,"Skipped",IF(Settings!$B$15<>"Ready","Invalid settings",IF(OR(D12<>1,COUNTIF($A$2:$A$49,A12)<>1,NOT(ISNUMBER(E12)),E12<0,NOT(ISNUMBER(F12)),F12<0,F12>1),"Invalid input",IF(F12=1,"Complete",IF(OR(L12<=0,COUNTIFS($C$2:C11,C12,$M$2:M11,"Blocked*")+COUNTIFS($C$2:C11,C12,$M$2:M11,"Invalid*")>0,AND(G12<>"",OR(IFERROR(INDEX($D$2:$D$11,MATCH(G12,$A$2:$A$11,0)),0)<>1,IFERROR(INDEX($M$2:$M$11,MATCH(G12,$A$2:$A$11,0)),"Blocked")="Blocked",LEFT(IFERROR(INDEX($M$2:$M$11,MATCH(G12,$A$2:$A$11,0)),"Invalid"),7)="Invalid")),AND(H12<>"",OR(IFERROR(INDEX($D$2:$D$11,MATCH(H12,$A$2:$A$11,0)),0)<>1,IFERROR(INDEX($M$2:$M$11,MATCH(H12,$A$2:$A$11,0)),"Blocked")="Blocked",LEFT(IFERROR(INDEX($M$2:$M$11,MATCH(H12,$A$2:$A$11,0)),"Invalid"),7)="Invalid")),AND(I12<>"",OR(IFERROR(INDEX($D$2:$D$11,MATCH(I12,$A$2:$A$11,0)),0)<>1,IFERROR(INDEX($M$2:$M$11,MATCH(I12,$A$2:$A$11,0)),"Blocked")="Blocked",LEFT(IFERROR(INDEX($M$2:$M$11,MATCH(I12,$A$2:$A$11,0)),"Invalid"),7)="Invalid")),AND(J12<>"",OR(IFERROR(INDEX($D$2:$D$11,MATCH(J12,$A$2:$A$11,0)),0)<>1,IFERROR(INDEX($M$2:$M$11,MATCH(J12,$A$2:$A$11,0)),"Blocked")="Blocked",LEFT(IFERROR(INDEX($M$2:$M$11,MATCH(J12,$A$2:$A$11,0)),"Invalid"),7)="Invalid"))),"Blocked","Planned"))))) -> Planned | N12: =IF(M12="Skipped",O11,IF(OR(M12="Planned",M12="Complete"),MAX(O11,IF(G12="",0,IFERROR(INDEX($O$2:$O$11,MATCH(G12,$A$2:$A$11,0)),0)),IF(H12="",0,IFERROR(INDEX($O$2:$O$11,MATCH(H12,$A$2:$A$11,0)),0)),IF(I12="",0,IFERROR(INDEX($O$2:$O$11,MATCH(I12,$A$2:$A$11,0)),0)),IF(J12="",0,IFERROR(INDEX($O$2:$O$11,MATCH(J12,$A$2:$A$11,0)),0))),"")) -> 183.52941 | O12: =IF(M12="Skipped",N12,IF(OR(M12="Planned",M12="Complete"),N12+IF(K12=0,0,K12/L12),"")) -> 197.64706 | P12: =IF(AND(M12="Planned",K12>0),WORKDAY.INTL(Settings!$B$2-1,INT(N12+0.000000001)+1,Settings!$B$4,Holidays!$A$2:$A$101),"") -> 46532 | Q12: =IF(AND(M12="Planned",K12>0),WORKDAY.INTL(Settings!$B$2-1,MAX(1,ROUNDUP(O12-0.000000001,0)),Settings!$B$4,Holidays!$A$2:$A$101),"") -> 46548 | R12: =IF(OR(M12="Planned",M12="Complete"),O12-N12,0) -> 14.117647 | S12: Produce a reproducible audit with missing data and duplicate-key checks. | T12: https://www.deep-ml.com/paths
A13: B04 | B13: Calculus gradients and optimization bridge | C13: Core | D13: =1 -> 1 | E13: =12 -> 12 | F13: =0 -> 0 | G13: B01 | K13: =IF(D13=0,0,IF(AND(ISNUMBER(E13),E13>=0,ISNUMBER(F13),F13>=0,F13<=1),E13*(1-F13)*(1+Settings!$B$5),0)) -> 14.4 | L13: =IFERROR(INDEX(Settings!$B$10:$B$12,MATCH(C13,{"Core","Practice","Delivery"},0)),0) -> 1.53 | M13: =IF(D13=0,"Skipped",IF(Settings!$B$15<>"Ready","Invalid settings",IF(OR(D13<>1,COUNTIF($A$2:$A$49,A13)<>1,NOT(ISNUMBER(E13)),E13<0,NOT(ISNUMBER(F13)),F13<0,F13>1),"Invalid input",IF(F13=1,"Complete",IF(OR(L13<=0,COUNTIFS($C$2:C12,C13,$M$2:M12,"Blocked*")+COUNTIFS($C$2:C12,C13,$M$2:M12,"Invalid*")>0,AND(G13<>"",OR(IFERROR(INDEX($D$2:$D$12,MATCH(G13,$A$2:$A$12,0)),0)<>1,IFERROR(INDEX($M$2:$M$12,MATCH(G13,$A$2:$A$12,0)),"Blocked")="Blocked",LEFT(IFERROR(INDEX($M$2:$M$12,MATCH(G13,$A$2:$A$12,0)),"Invalid"),7)="Invalid")),AND(H13<>"",OR(IFERROR(INDEX($D$2:$D$12,MATCH(H13,$A$2:$A$12,0)),0)<>1,IFERROR(INDEX($M$2:$M$12,MATCH(H13,$A$2:$A$12,0)),"Blocked")="Blocked",LEFT(IFERROR(INDEX($M$2:$M$12,MATCH(H13,$A$2:$A$12,0)),"Invalid"),7)="Invalid")),AND(I13<>"",OR(IFERROR(INDEX($D$2:$D$12,MATCH(I13,$A$2:$A$12,0)),0)<>1,IFERROR(INDEX($M$2:$M$12,MATCH(I13,$A$2:$A$12,0)),"Blocked")="Blocked",LEFT(IFERROR(INDEX($M$2:$M$12,MATCH(I13,$A$2:$A$12,0)),"Invalid"),7)="Invalid")),AND(J13<>"",OR(IFERROR(INDEX($D$2:$D$12,MATCH(J13,$A$2:$A$12,0)),0)<>1,IFERROR(INDEX($M$2:$M$12,MATCH(J13,$A$2:$A$12,0)),"Blocked")="Blocked",LEFT(IFERROR(INDEX($M$2:$M$12,MATCH(J13,$A$2:$A$12,0)),"Invalid"),7)="Invalid"))),"Blocked","Planned"))))) -> Planned | N13: =IF(M13="Skipped",O12,IF(OR(M13="Planned",M13="Complete"),MAX(O12,IF(G13="",0,IFERROR(INDEX($O$2:$O$12,MATCH(G13,$A$2:$A$12,0)),0)),IF(H13="",0,IFERROR(INDEX($O$2:$O$12,MATCH(H13,$A$2:$A$12,0)),0)),IF(I13="",0,IFERROR(INDEX($O$2:$O$12,MATCH(I13,$A$2:$A$12,0)),0)),IF(J13="",0,IFERROR(INDEX($O$2:$O$12,MATCH(J13,$A$2:$A$12,0)),0))),"")) -> 197.64706 | O13: =IF(M13="Skipped",N13,IF(OR(M13="Planned",M13="Complete"),N13+IF(K13=0,0,K13/L13),"")) -> 207.05882 | P13: =IF(AND(M13="Planned",K13>0),WORKDAY.INTL(Settings!$B$2-1,INT(N13+0.000000001)+1,Settings!$B$4,Holidays!$A$2:$A$101),"") -> 46548 | Q13: =IF(AND(M13="Planned",K13>0),WORKDAY.INTL(Settings!$B$2-1,MAX(1,ROUNDUP(O13-0.000000001,0)),Settings!$B$4,Holidays!$A$2:$A$101),"") -> 46560 | R13: =IF(OR(M13="Planned",M13="Complete"),O13-N13,0) -> 9.4117647 | S13: Implement and check one gradient update and learning-rate failure. | T13: https://www.deep-ml.com/paths
A14: B05 | B14: Classical ML baselines and leakage bridge | C14: Core | D14: =1 -> 1 | E14: =26 -> 26 | F14: =0 -> 0 | G14: B02 | H14: B03 | I14: B04 | K14: =IF(D14=0,0,IF(AND(ISNUMBER(E14),E14>=0,ISNUMBER(F14),F14>=0,F14<=1),E14*(1-F14)*(1+Settings!$B$5),0)) -> 31.2 | L14: =IFERROR(INDEX(Settings!$B$10:$B$12,MATCH(C14,{"Core","Practice","Delivery"},0)),0) -> 1.53 | M14: =IF(D14=0,"Skipped",IF(Settings!$B$15<>"Ready","Invalid settings",IF(OR(D14<>1,COUNTIF($A$2:$A$49,A14)<>1,NOT(ISNUMBER(E14)),E14<0,NOT(ISNUMBER(F14)),F14<0,F14>1),"Invalid input",IF(F14=1,"Complete",IF(OR(L14<=0,COUNTIFS($C$2:C13,C14,$M$2:M13,"Blocked*")+COUNTIFS($C$2:C13,C14,$M$2:M13,"Invalid*")>0,AND(G14<>"",OR(IFERROR(INDEX($D$2:$D$13,MATCH(G14,$A$2:$A$13,0)),0)<>1,IFERROR(INDEX($M$2:$M$13,MATCH(G14,$A$2:$A$13,0)),"Blocked")="Blocked",LEFT(IFERROR(INDEX($M$2:$M$13,MATCH(G14,$A$2:$A$13,0)),"Invalid"),7)="Invalid")),AND(H14<>"",OR(IFERROR(INDEX($D$2:$D$13,MATCH(H14,$A$2:$A$13,0)),0)<>1,IFERROR(INDEX($M$2:$M$13,MATCH(H14,$A$2:$A$13,0)),"Blocked")="Blocked",LEFT(IFERROR(INDEX($M$2:$M$13,MATCH(H14,$A$2:$A$13,0)),"Invalid"),7)="Invalid")),AND(I14<>"",OR(IFERROR(INDEX($D$2:$D$13,MATCH(I14,$A$2:$A$13,0)),0)<>1,IFERROR(INDEX($M$2:$M$13,MATCH(I14,$A$2:$A$13,0)),"Blocked")="Blocked",LEFT(IFERROR(INDEX($M$2:$M$13,MATCH(I14,$A$2:$A$13,0)),"Invalid"),7)="Invalid")),AND(J14<>"",OR(IFERROR(INDEX($D$2:$D$13,MATCH(J14,$A$2:$A$13,0)),0)<>1,IFERROR(INDEX($M$2:$M$13,MATCH(J14,$A$2:$A$13,0)),"Blocked")="Blocked",LEFT(IFERROR(INDEX($M$2:$M$13,MATCH(J14,$A$2:$A$13,0)),"Invalid"),7)="Invalid"))),"Blocked","Planned"))))) -> Planned | N14: =IF(M14="Skipped",O13,IF(OR(M14="Planned",M14="Complete"),MAX(O13,IF(G14="",0,IFERROR(INDEX($O$2:$O$13,MATCH(G14,$A$2:$A$13,0)),0)),IF(H14="",0,IFERROR(INDEX($O$2:$O$13,MATCH(H14,$A$2:$A$13,0)),0)),IF(I14="",0,IFERROR(INDEX($O$2:$O$13,MATCH(I14,$A$2:$A$13,0)),0)),IF(J14="",0,IFERROR(INDEX($O$2:$O$13,MATCH(J14,$A$2:$A$13,0)),0))),"")) -> 207.05882 | O14: =IF(M14="Skipped",N14,IF(OR(M14="Planned",M14="Complete"),N14+IF(K14=0,0,K14/L14),"")) -> 227.45098 | P14: =IF(AND(M14="Planned",K14>0),WORKDAY.INTL(Settings!$B$2-1,INT(N14+0.000000001)+1,Settings!$B$4,Holidays!$A$2:$A$101),"") -> 46560 | Q14: =IF(AND(M14="Planned",K14>0),WORKDAY.INTL(Settings!$B$2-1,MAX(1,ROUNDUP(O14-0.000000001,0)),Settings!$B$4,Holidays!$A$2:$A$101),"") -> 46583 | R14: =IF(OR(M14="Planned",M14="Complete"),O14-N14,0) -> 20.392157 | S14: Compare regression or classification against a baseline using leakage-safe splits. | T14: https://www.deep-ml.com/paths
A15: B06 | B15: Metrics thresholds and experimental reasoning bridge | C15: Core | D15: =1 -> 1 | E15: =20 -> 20 | F15: =0 -> 0 | G15: B05 | K15: =IF(D15=0,0,IF(AND(ISNUMBER(E15),E15>=0,ISNUMBER(F15),F15>=0,F15<=1),E15*(1-F15)*(1+Settings!$B$5),0)) -> 24 | L15: =IFERROR(INDEX(Settings!$B$10:$B$12,MATCH(C15,{"Core","Practice","Delivery"},0)),0) -> 1.53 | M15: =IF(D15=0,"Skipped",IF(Settings!$B$15<>"Ready","Invalid settings",IF(OR(D15<>1,COUNTIF($A$2:$A$49,A15)<>1,NOT(ISNUMBER(E15)),E15<0,NOT(ISNUMBER(F15)),F15<0,F15>1),"Invalid input",IF(F15=1,"Complete",IF(OR(L15<=0,COUNTIFS($C$2:C14,C15,$M$2:M14,"Blocked*")+COUNTIFS($C$2:C14,C15,$M$2:M14,"Invalid*")>0,AND(G15<>"",OR(IFERROR(INDEX($D$2:$D$14,MATCH(G15,$A$2:$A$14,0)),0)<>1,IFERROR(INDEX($M$2:$M$14,MATCH(G15,$A$2:$A$14,0)),"Blocked")="Blocked",LEFT(IFERROR(INDEX($M$2:$M$14,MATCH(G15,$A$2:$A$14,0)),"Invalid"),7)="Invalid")),AND(H15<>"",OR(IFERROR(INDEX($D$2:$D$14,MATCH(H15,$A$2:$A$14,0)),0)<>1,IFERROR(INDEX($M$2:$M$14,MATCH(H15,$A$2:$A$14,0)),"Blocked")="Blocked",LEFT(IFERROR(INDEX($M$2:$M$14,MATCH(H15,$A$2:$A$14,0)),"Invalid"),7)="Invalid")),AND(I15<>"",OR(IFERROR(INDEX($D$2:$D$14,MATCH(I15,$A$2:$A$14,0)),0)<>1,IFERROR(INDEX($M$2:$M$14,MATCH(I15,$A$2:$A$14,0)),"Blocked")="Blocked",LEFT(IFERROR(INDEX($M$2:$M$14,MATCH(I15,$A$2:$A$14,0)),"Invalid"),7)="Invalid")),AND(J15<>"",OR(IFERROR(INDEX($D$2:$D$14,MATCH(J15,$A$2:$A$14,0)),0)<>1,IFERROR(INDEX($M$2:$M$14,MATCH(J15,$A$2:$A$14,0)),"Blocked")="Blocked",LEFT(IFERROR(INDEX($M$2:$M$14,MATCH(J15,$A$2:$A$14,0)),"Invalid"),7)="Invalid"))),"Blocked","Planned"))))) -> Planned | N15: =IF(M15="Skipped",O14,IF(OR(M15="Planned",M15="Complete"),MAX(O14,IF(G15="",0,IFERROR(INDEX($O$2:$O$14,MATCH(G15,$A$2:$A$14,0)),0)),IF(H15="",0,IFERROR(INDEX($O$2:$O$14,MATCH(H15,$A$2:$A$14,0)),0)),IF(I15="",0,IFERROR(INDEX($O$2:$O$14,MATCH(I15,$A$2:$A$14,0)),0)),IF(J15="",0,IFERROR(INDEX($O$2:$O$14,MATCH(J15,$A$2:$A$14,0)),0))),"")) -> 227.45098 | O15: =IF(M15="Skipped",N15,IF(OR(M15="Planned",M15="Complete"),N15+IF(K15=0,0,K15/L15),"")) -> 243.13725 | P15: =IF(AND(M15="Planned",K15>0),WORKDAY.INTL(Settings!$B$2-1,INT(N15+0.000000001)+1,Settings!$B$4,Holidays!$A$2:$A$101),"") -> 46583 | Q15: =IF(AND(M15="Planned",K15>0),WORKDAY.INTL(Settings!$B$2-1,MAX(1,ROUNDUP(O15-0.000000001,0)),Settings!$B$4,Holidays!$A$2:$A$101),"") -> 46602 | R15: =IF(OR(M15="Planned",M15="Complete"),O15-N15,0) -> 15.686275 | S15: Choose task metrics and distinguish a score difference from a causal claim. | T15: https://datalemur.com/
A16: A01 | B16: LLM behavior and model selection | C16: Core | D16: =1 -> 1 | E16: =20 -> 20 | F16: =0 -> 0 | G16: B05 | K16: =IF(D16=0,0,IF(AND(ISNUMBER(E16),E16>=0,ISNUMBER(F16),F16>=0,F16<=1),E16*(1-F16)*(1+Settings!$B$5),0)) -> 24 | L16: =IFERROR(INDEX(Settings!$B$10:$B$12,MATCH(C16,{"Core","Practice","Delivery"},0)),0) -> 1.53 | M16: =IF(D16=0,"Skipped",IF(Settings!$B$15<>"Ready","Invalid settings",IF(OR(D16<>1,COUNTIF($A$2:$A$49,A16)<>1,NOT(ISNUMBER(E16)),E16<0,NOT(ISNUMBER(F16)),F16<0,F16>1),"Invalid input",IF(F16=1,"Complete",IF(OR(L16<=0,COUNTIFS($C$2:C15,C16,$M$2:M15,"Blocked*")+COUNTIFS($C$2:C15,C16,$M$2:M15,"Invalid*")>0,AND(G16<>"",OR(IFERROR(INDEX($D$2:$D$15,MATCH(G16,$A$2:$A$15,0)),0)<>1,IFERROR(INDEX($M$2:$M$15,MATCH(G16,$A$2:$A$15,0)),"Blocked")="Blocked",LEFT(IFERROR(INDEX($M$2:$M$15,MATCH(G16,$A$2:$A$15,0)),"Invalid"),7)="Invalid")),AND(H16<>"",OR(IFERROR(INDEX($D$2:$D$15,MATCH(H16,$A$2:$A$15,0)),0)<>1,IFERROR(INDEX($M$2:$M$15,MATCH(H16,$A$2:$A$15,0)),"Blocked")="Blocked",LEFT(IFERROR(INDEX($M$2:$M$15,MATCH(H16,$A$2:$A$15,0)),"Invalid"),7)="Invalid")),AND(I16<>"",OR(IFERROR(INDEX($D$2:$D$15,MATCH(I16,$A$2:$A$15,0)),0)<>1,IFERROR(INDEX($M$2:$M$15,MATCH(I16,$A$2:$A$15,0)),"Blocked")="Blocked",LEFT(IFERROR(INDEX($M$2:$M$15,MATCH(I16,$A$2:$A$15,0)),"Invalid"),7)="Invalid")),AND(J16<>"",OR(IFERROR(INDEX($D$2:$D$15,MATCH(J16,$A$2:$A$15,0)),0)<>1,IFERROR(INDEX($M$2:$M$15,MATCH(J16,$A$2:$A$15,0)),"Blocked")="Blocked",LEFT(IFERROR(INDEX($M$2:$M$15,MATCH(J16,$A$2:$A$15,0)),"Invalid"),7)="Invalid"))),"Blocked","Planned"))))) -> Planned | N16: =IF(M16="Skipped",O15,IF(OR(M16="Planned",M16="Complete"),MAX(O15,IF(G16="",0,IFERROR(INDEX($O$2:$O$15,MATCH(G16,$A$2:$A$15,0)),0)),IF(H16="",0,IFERROR(INDEX($O$2:$O$15,MATCH(H16,$A$2:$A$15,0)),0)),IF(I16="",0,IFERROR(INDEX($O$2:$O$15,MATCH(I16,$A$2:$A$15,0)),0)),IF(J16="",0,IFERROR(INDEX($O$2:$O$15,MATCH(J16,$A$2:$A$15,0)),0))),"")) -> 243.13725 | O16: =IF(M16="Skipped",N16,IF(OR(M16="Planned",M16="Complete"),N16+IF(K16=0,0,K16/L16),"")) -> 258.82353 | P16: =IF(AND(M16="Planned",K16>0),WORKDAY.INTL(Settings!$B$2-1,INT(N16+0.000000001)+1,Settings!$B$4,Holidays!$A$2:$A$101),"") -> 46602 | Q16: =IF(AND(M16="Planned",K16>0),WORKDAY.INTL(Settings!$B$2-1,MAX(1,ROUNDUP(O16-0.000000001,0)),Settings!$B$4,Holidays!$A$2:$A$101),"") -> 46619 | R16: =IF(OR(M16="Planned",M16="Complete"),O16-N16,0) -> 15.686275 | S16: Compare candidate approaches with quality, policy, latency, and cost evidence. | T16: https://roadmap.sh/ai-engineer
A17: A02 | B17: Prompt context and prompt lifecycle | C17: Core | D17: =1 -> 1 | E17: =22 -> 22 | F17: =0 -> 0 | G17: A01 | K17: =IF(D17=0,0,IF(AND(ISNUMBER(E17),E17>=0,ISNUMBER(F17),F17>=0,F17<=1),E17*(1-F17)*(1+Settings!$B$5),0)) -> 26.4 | L17: =IFERROR(INDEX(Settings!$B$10:$B$12,MATCH(C17,{"Core","Practice","Delivery"},0)),0) -> 1.53 | M17: =IF(D17=0,"Skipped",IF(Settings!$B$15<>"Ready","Invalid settings",IF(OR(D17<>1,COUNTIF($A$2:$A$49,A17)<>1,NOT(ISNUMBER(E17)),E17<0,NOT(ISNUMBER(F17)),F17<0,F17>1),"Invalid input",IF(F17=1,"Complete",IF(OR(L17<=0,COUNTIFS($C$2:C16,C17,$M$2:M16,"Blocked*")+COUNTIFS($C$2:C16,C17,$M$2:M16,"Invalid*")>0,AND(G17<>"",OR(IFERROR(INDEX($D$2:$D$16,MATCH(G17,$A$2:$A$16,0)),0)<>1,IFERROR(INDEX($M$2:$M$16,MATCH(G17,$A$2:$A$16,0)),"Blocked")="Blocked",LEFT(IFERROR(INDEX($M$2:$M$16,MATCH(G17,$A$2:$A$16,0)),"Invalid"),7)="Invalid")),AND(H17<>"",OR(IFERROR(INDEX($D$2:$D$16,MATCH(H17,$A$2:$A$16,0)),0)<>1,IFERROR(INDEX($M$2:$M$16,MATCH(H17,$A$2:$A$16,0)),"Blocked")="Blocked",LEFT(IFERROR(INDEX($M$2:$M$16,MATCH(H17,$A$2:$A$16,0)),"Invalid"),7)="Invalid")),AND(I17<>"",OR(IFERROR(INDEX($D$2:$D$16,MATCH(I17,$A$2:$A$16,0)),0)<>1,IFERROR(INDEX($M$2:$M$16,MATCH(I17,$A$2:$A$16,0)),"Blocked")="Blocked",LEFT(IFERROR(INDEX($M$2:$M$16,MATCH(I17,$A$2:$A$16,0)),"Invalid"),7)="Invalid")),AND(J17<>"",OR(IFERROR(INDEX($D$2:$D$16,MATCH(J17,$A$2:$A$16,0)),0)<>1,IFERROR(INDEX($M$2:$M$16,MATCH(J17,$A$2:$A$16,0)),"Blocked")="Blocked",LEFT(IFERROR(INDEX($M$2:$M$16,MATCH(J17,$A$2:$A$16,0)),"Invalid"),7)="Invalid"))),"Blocked","Planned"))))) -> Planned | N17: =IF(M17="Skipped",O16,IF(OR(M17="Planned",M17="Complete"),MAX(O16,IF(G17="",0,IFERROR(INDEX($O$2:$O$16,MATCH(G17,$A$2:$A$16,0)),0)),IF(H17="",0,IFERROR(INDEX($O$2:$O$16,MATCH(H17,$A$2:$A$16,0)),0)),IF(I17="",0,IFERROR(INDEX($O$2:$O$16,MATCH(I17,$A$2:$A$16,0)),0)),IF(J17="",0,IFERROR(INDEX($O$2:$O$16,MATCH(J17,$A$2:$A$16,0)),0))),"")) -> 258.82353 | O17: =IF(M17="Skipped",N17,IF(OR(M17="Planned",M17="Complete"),N17+IF(K17=0,0,K17/L17),"")) -> 276.07843 | P17: =IF(AND(M17="Planned",K17>0),WORKDAY.INTL(Settings!$B$2-1,INT(N17+0.000000001)+1,Settings!$B$4,Holidays!$A$2:$A$101),"") -> 46619 | Q17: =IF(AND(M17="Planned",K17>0),WORKDAY.INTL(Settings!$B$2-1,MAX(1,ROUNDUP(O17-0.000000001,0)),Settings!$B$4,Holidays!$A$2:$A$101),"") -> 46640 | R17: =IF(OR(M17="Planned",M17="Complete"),O17-N17,0) -> 17.254902 | S17: Version a schema-constrained prompt and a permission-filtered context packet. | T17: https://roadmap.sh/prompt-engineering
A18: A03 | B18: Retrieval embeddings and vector stores | C18: Core | D18: =1 -> 1 | E18: =30 -> 30 | F18: =0 -> 0 | G18: A02 | H18: F08 | K18: =IF(D18=0,0,IF(AND(ISNUMBER(E18),E18>=0,ISNUMBER(F18),F18>=0,F18<=1),E18*(1-F18)*(1+Settings!$B$5),0)) -> 36 | L18: =IFERROR(INDEX(Settings!$B$10:$B$12,MATCH(C18,{"Core","Practice","Delivery"},0)),0) -> 1.53 | M18: =IF(D18=0,"Skipped",IF(Settings!$B$15<>"Ready","Invalid settings",IF(OR(D18<>1,COUNTIF($A$2:$A$49,A18)<>1,NOT(ISNUMBER(E18)),E18<0,NOT(ISNUMBER(F18)),F18<0,F18>1),"Invalid input",IF(F18=1,"Complete",IF(OR(L18<=0,COUNTIFS($C$2:C17,C18,$M$2:M17,"Blocked*")+COUNTIFS($C$2:C17,C18,$M$2:M17,"Invalid*")>0,AND(G18<>"",OR(IFERROR(INDEX($D$2:$D$17,MATCH(G18,$A$2:$A$17,0)),0)<>1,IFERROR(INDEX($M$2:$M$17,MATCH(G18,$A$2:$A$17,0)),"Blocked")="Blocked",LEFT(IFERROR(INDEX($M$2:$M$17,MATCH(G18,$A$2:$A$17,0)),"Invalid"),7)="Invalid")),AND(H18<>"",OR(IFERROR(INDEX($D$2:$D$17,MATCH(H18,$A$2:$A$17,0)),0)<>1,IFERROR(INDEX($M$2:$M$17,MATCH(H18,$A$2:$A$17,0)),"Blocked")="Blocked",LEFT(IFERROR(INDEX($M$2:$M$17,MATCH(H18,$A$2:$A$17,0)),"Invalid"),7)="Invalid")),AND(I18<>"",OR(IFERROR(INDEX($D$2:$D$17,MATCH(I18,$A$2:$A$17,0)),0)<>1,IFERROR(INDEX($M$2:$M$17,MATCH(I18,$A$2:$A$17,0)),"Blocked")="Blocked",LEFT(IFERROR(INDEX($M$2:$M$17,MATCH(I18,$A$2:$A$17,0)),"Invalid"),7)="Invalid")),AND(J18<>"",OR(IFERROR(INDEX($D$2:$D$17,MATCH(J18,$A$2:$A$17,0)),0)<>1,IFERROR(INDEX($M$2:$M$17,MATCH(J18,$A$2:$A$17,0)),"Blocked")="Blocked",LEFT(IFERROR(INDEX($M$2:$M$17,MATCH(J18,$A$2:$A$17,0)),"Invalid"),7)="Invalid"))),"Blocked","Planned"))))) -> Planned | N18: =IF(M18="Skipped",O17,IF(OR(M18="Planned",M18="Complete"),MAX(O17,IF(G18="",0,IFERROR(INDEX($O$2:$O$17,MATCH(G18,$A$2:$A$17,0)),0)),IF(H18="",0,IFERROR(INDEX($O$2:$O$17,MATCH(H18,$A$2:$A$17,0)),0)),IF(I18="",0,IFERROR(INDEX($O$2:$O$17,MATCH(I18,$A$2:$A$17,0)),0)),IF(J18="",0,IFERROR(INDEX($O$2:$O$17,MATCH(J18,$A$2:$A$17,0)),0))),"")) -> 276.07843 | O18: =IF(M18="Skipped",N18,IF(OR(M18="Planned",M18="Complete"),N18+IF(K18=0,0,K18/L18),"")) -> 299.60784 | P18: =IF(AND(M18="Planned",K18>0),WORKDAY.INTL(Settings!$B$2-1,INT(N18+0.000000001)+1,Settings!$B$4,Holidays!$A$2:$A$101),"") -> 46640 | Q18: =IF(AND(M18="Planned",K18>0),WORKDAY.INTL(Settings!$B$2-1,MAX(1,ROUNDUP(O18-0.000000001,0)),Settings!$B$4,Holidays!$A$2:$A$101),"") -> 46667 | R18: =IF(OR(M18="Planned",M18="Complete"),O18-N18,0) -> 23.529412 | S18: Measure retrieval separately and verify citation support and tenant isolation. | T18: https://roadmap.sh/ai-engineer
A19: A04 | B19: Evaluation pipelines and regression analysis | C19: Core | D19: =1 -> 1 | E19: =26 -> 26 | F19: =0 -> 0 | G19: A03 | H19: B06 | K19: =IF(D19=0,0,IF(AND(ISNUMBER(E19),E19>=0,ISNUMBER(F19),F19>=0,F19<=1),E19*(1-F19)*(1+Settings!$B$5),0)) -> 31.2 | L19: =IFERROR(INDEX(Settings!$B$10:$B$12,MATCH(C19,{"Core","Practice","Delivery"},0)),0) -> 1.53 | M19: =IF(D19=0,"Skipped",IF(Settings!$B$15<>"Ready","Invalid settings",IF(OR(D19<>1,COUNTIF($A$2:$A$49,A19)<>1,NOT(ISNUMBER(E19)),E19<0,NOT(ISNUMBER(F19)),F19<0,F19>1),"Invalid input",IF(F19=1,"Complete",IF(OR(L19<=0,COUNTIFS($C$2:C18,C19,$M$2:M18,"Blocked*")+COUNTIFS($C$2:C18,C19,$M$2:M18,"Invalid*")>0,AND(G19<>"",OR(IFERROR(INDEX($D$2:$D$18,MATCH(G19,$A$2:$A$18,0)),0)<>1,IFERROR(INDEX($M$2:$M$18,MATCH(G19,$A$2:$A$18,0)),"Blocked")="Blocked",LEFT(IFERROR(INDEX($M$2:$M$18,MATCH(G19,$A$2:$A$18,0)),"Invalid"),7)="Invalid")),AND(H19<>"",OR(IFERROR(INDEX($D$2:$D$18,MATCH(H19,$A$2:$A$18,0)),0)<>1,IFERROR(INDEX($M$2:$M$18,MATCH(H19,$A$2:$A$18,0)),"Blocked")="Blocked",LEFT(IFERROR(INDEX($M$2:$M$18,MATCH(H19,$A$2:$A$18,0)),"Invalid"),7)="Invalid")),AND(I19<>"",OR(IFERROR(INDEX($D$2:$D$18,MATCH(I19,$A$2:$A$18,0)),0)<>1,IFERROR(INDEX($M$2:$M$18,MATCH(I19,$A$2:$A$18,0)),"Blocked")="Blocked",LEFT(IFERROR(INDEX($M$2:$M$18,MATCH(I19,$A$2:$A$18,0)),"Invalid"),7)="Invalid")),AND(J19<>"",OR(IFERROR(INDEX($D$2:$D$18,MATCH(J19,$A$2:$A$18,0)),0)<>1,IFERROR(INDEX($M$2:$M$18,MATCH(J19,$A$2:$A$18,0)),"Blocked")="Blocked",LEFT(IFERROR(INDEX($M$2:$M$18,MATCH(J19,$A$2:$A$18,0)),"Invalid"),7)="Invalid"))),"Blocked","Planned"))))) -> Planned | N19: =IF(M19="Skipped",O18,IF(OR(M19="Planned",M19="Complete"),MAX(O18,IF(G19="",0,IFERROR(INDEX($O$2:$O$18,MATCH(G19,$A$2:$A$18,0)),0)),IF(H19="",0,IFERROR(INDEX($O$2:$O$18,MATCH(H19,$A$2:$A$18,0)),0)),IF(I19="",0,IFERROR(INDEX($O$2:$O$18,MATCH(I19,$A$2:$A$18,0)),0)),IF(J19="",0,IFERROR(INDEX($O$2:$O$18,MATCH(J19,$A$2:$A$18,0)),0))),"")) -> 299.60784 | O19: =IF(M19="Skipped",N19,IF(OR(M19="Planned",M19="Complete"),N19+IF(K19=0,0,K19/L19),"")) -> 320 | P19: =IF(AND(M19="Planned",K19>0),WORKDAY.INTL(Settings!$B$2-1,INT(N19+0.000000001)+1,Settings!$B$4,Holidays!$A$2:$A$101),"") -> 46667 | Q19: =IF(AND(M19="Planned",K19>0),WORKDAY.INTL(Settings!$B$2-1,MAX(1,ROUNDUP(O19-0.000000001,0)),Settings!$B$4,Holidays!$A$2:$A$101),"") -> 46690 | R19: =IF(OR(M19="Planned",M19="Complete"),O19-N19,0) -> 20.392157 | S19: Produce a versioned held-out report with errors separate from poor scores. | T19: https://eugeneyan.com/writing/
A20: S01 | B20: Authentication API and system security | C20: Core | D20: =1 -> 1 | E20: =24 -> 24 | F20: =0 -> 0 | G20: F05 | K20: =IF(D20=0,0,IF(AND(ISNUMBER(E20),E20>=0,ISNUMBER(F20),F20>=0,F20<=1),E20*(1-F20)*(1+Settings!$B$5),0)) -> 28.8 | L20: =IFERROR(INDEX(Settings!$B$10:$B$12,MATCH(C20,{"Core","Practice","Delivery"},0)),0) -> 1.53 | M20: =IF(D20=0,"Skipped",IF(Settings!$B$15<>"Ready","Invalid settings",IF(OR(D20<>1,COUNTIF($A$2:$A$49,A20)<>1,NOT(ISNUMBER(E20)),E20<0,NOT(ISNUMBER(F20)),F20<0,F20>1),"Invalid input",IF(F20=1,"Complete",IF(OR(L20<=0,COUNTIFS($C$2:C19,C20,$M$2:M19,"Blocked*")+COUNTIFS($C$2:C19,C20,$M$2:M19,"Invalid*")>0,AND(G20<>"",OR(IFERROR(INDEX($D$2:$D$19,MATCH(G20,$A$2:$A$19,0)),0)<>1,IFERROR(INDEX($M$2:$M$19,MATCH(G20,$A$2:$A$19,0)),"Blocked")="Blocked",LEFT(IFERROR(INDEX($M$2:$M$19,MATCH(G20,$A$2:$A$19,0)),"Invalid"),7)="Invalid")),AND(H20<>"",OR(IFERROR(INDEX($D$2:$D$19,MATCH(H20,$A$2:$A$19,0)),0)<>1,IFERROR(INDEX($M$2:$M$19,MATCH(H20,$A$2:$A$19,0)),"Blocked")="Blocked",LEFT(IFERROR(INDEX($M$2:$M$19,MATCH(H20,$A$2:$A$19,0)),"Invalid"),7)="Invalid")),AND(I20<>"",OR(IFERROR(INDEX($D$2:$D$19,MATCH(I20,$A$2:$A$19,0)),0)<>1,IFERROR(INDEX($M$2:$M$19,MATCH(I20,$A$2:$A$19,0)),"Blocked")="Blocked",LEFT(IFERROR(INDEX($M$2:$M$19,MATCH(I20,$A$2:$A$19,0)),"Invalid"),7)="Invalid")),AND(J20<>"",OR(IFERROR(INDEX($D$2:$D$19,MATCH(J20,$A$2:$A$19,0)),0)<>1,IFERROR(INDEX($M$2:$M$19,MATCH(J20,$A$2:$A$19,0)),"Blocked")="Blocked",LEFT(IFERROR(INDEX($M$2:$M$19,MATCH(J20,$A$2:$A$19,0)),"Invalid"),7)="Invalid"))),"Blocked","Planned"))))) -> Planned | N20: =IF(M20="Skipped",O19,IF(OR(M20="Planned",M20="Complete"),MAX(O19,IF(G20="",0,IFERROR(INDEX($O$2:$O$19,MATCH(G20,$A$2:$A$19,0)),0)),IF(H20="",0,IFERROR(INDEX($O$2:$O$19,MATCH(H20,$A$2:$A$19,0)),0)),IF(I20="",0,IFERROR(INDEX($O$2:$O$19,MATCH(I20,$A$2:$A$19,0)),0)),IF(J20="",0,IFERROR(INDEX($O$2:$O$19,MATCH(J20,$A$2:$A$19,0)),0))),"")) -> 320 | O20: =IF(M20="Skipped",N20,IF(OR(M20="Planned",M20="Complete"),N20+IF(K20=0,0,K20/L20),"")) -> 338.82353 | P20: =IF(AND(M20="Planned",K20>0),WORKDAY.INTL(Settings!$B$2-1,INT(N20+0.000000001)+1,Settings!$B$4,Holidays!$A$2:$A$101),"") -> 46692 | Q20: =IF(AND(M20="Planned",K20>0),WORKDAY.INTL(Settings!$B$2-1,MAX(1,ROUNDUP(O20-0.000000001,0)),Settings!$B$4,Holidays!$A$2:$A$101),"") -> 46713 | R20: =IF(OR(M20="Planned",M20="Complete"),O20-N20,0) -> 18.823529 | S20: Reject invalid credentials, cross-tenant access, and unsafe output use. | T20: https://genai.owasp.org/llm-top-10/
A21: A05 | B21: Trusted tools state and integration | C21: Core | D21: =1 -> 1 | E21: =26 -> 26 | F21: =0 -> 0 | G21: A04 | H21: S01 | K21: =IF(D21=0,0,IF(AND(ISNUMBER(E21),E21>=0,ISNUMBER(F21),F21>=0,F21<=1),E21*(1-F21)*(1+Settings!$B$5),0)) -> 31.2 | L21: =IFERROR(INDEX(Settings!$B$10:$B$12,MATCH(C21,{"Core","Practice","Delivery"},0)),0) -> 1.53 | M21: =IF(D21=0,"Skipped",IF(Settings!$B$15<>"Ready","Invalid settings",IF(OR(D21<>1,COUNTIF($A$2:$A$49,A21)<>1,NOT(ISNUMBER(E21)),E21<0,NOT(ISNUMBER(F21)),F21<0,F21>1),"Invalid input",IF(F21=1,"Complete",IF(OR(L21<=0,COUNTIFS($C$2:C20,C21,$M$2:M20,"Blocked*")+COUNTIFS($C$2:C20,C21,$M$2:M20,"Invalid*")>0,AND(G21<>"",OR(IFERROR(INDEX($D$2:$D$20,MATCH(G21,$A$2:$A$20,0)),0)<>1,IFERROR(INDEX($M$2:$M$20,MATCH(G21,$A$2:$A$20,0)),"Blocked")="Blocked",LEFT(IFERROR(INDEX($M$2:$M$20,MATCH(G21,$A$2:$A$20,0)),"Invalid"),7)="Invalid")),AND(H21<>"",OR(IFERROR(INDEX($D$2:$D$20,MATCH(H21,$A$2:$A$20,0)),0)<>1,IFERROR(INDEX($M$2:$M$20,MATCH(H21,$A$2:$A$20,0)),"Blocked")="Blocked",LEFT(IFERROR(INDEX($M$2:$M$20,MATCH(H21,$A$2:$A$20,0)),"Invalid"),7)="Invalid")),AND(I21<>"",OR(IFERROR(INDEX($D$2:$D$20,MATCH(I21,$A$2:$A$20,0)),0)<>1,IFERROR(INDEX($M$2:$M$20,MATCH(I21,$A$2:$A$20,0)),"Blocked")="Blocked",LEFT(IFERROR(INDEX($M$2:$M$20,MATCH(I21,$A$2:$A$20,0)),"Invalid"),7)="Invalid")),AND(J21<>"",OR(IFERROR(INDEX($D$2:$D$20,MATCH(J21,$A$2:$A$20,0)),0)<>1,IFERROR(INDEX($M$2:$M$20,MATCH(J21,$A$2:$A$20,0)),"Blocked")="Blocked",LEFT(IFERROR(INDEX($M$2:$M$20,MATCH(J21,$A$2:$A$20,0)),"Invalid"),7)="Invalid"))),"Blocked","Planned"))))) -> Planned | N21: =IF(M21="Skipped",O20,IF(OR(M21="Planned",M21="Complete"),MAX(O20,IF(G21="",0,IFERROR(INDEX($O$2:$O$20,MATCH(G21,$A$2:$A$20,0)),0)),IF(H21="",0,IFERROR(INDEX($O$2:$O$20,MATCH(H21,$A$2:$A$20,0)),0)),IF(I21="",0,IFERROR(INDEX($O$2:$O$20,MATCH(I21,$A$2:$A$20,0)),0)),IF(J21="",0,IFERROR(INDEX($O$2:$O$20,MATCH(J21,$A$2:$A$20,0)),0))),"")) -> 338.82353 | O21: =IF(M21="Skipped",N21,IF(OR(M21="Planned",M21="Complete"),N21+IF(K21=0,0,K21/L21),"")) -> 359.21569 | P21: =IF(AND(M21="Planned",K21>0),WORKDAY.INTL(Settings!$B$2-1,INT(N21+0.000000001)+1,Settings!$B$4,Holidays!$A$2:$A$101),"") -> 46713 | Q21: =IF(AND(M21="Planned",K21>0),WORKDAY.INTL(Settings!$B$2-1,MAX(1,ROUNDUP(O21-0.000000001,0)),Settings!$B$4,Holidays!$A$2:$A$101),"") -> 46737 | R21: =IF(OR(M21="Planned",M21="Complete"),O21-N21,0) -> 20.392157 | S21: Reject malformed or unauthorized tool calls and recover a partial integration failure. | T21: https://roadmap.sh/ai-agents
A22: A06 | B22: Bounded agents and architecture tradeoffs | C22: Core | D22: =1 -> 1 | E22: =24 -> 24 | F22: =0 -> 0 | G22: A05 | K22: =IF(D22=0,0,IF(AND(ISNUMBER(E22),E22>=0,ISNUMBER(F22),F22>=0,F22<=1),E22*(1-F22)*(1+Settings!$B$5),0)) -> 28.8 | L22: =IFERROR(INDEX(Settings!$B$10:$B$12,MATCH(C22,{"Core","Practice","Delivery"},0)),0) -> 1.53 | M22: =IF(D22=0,"Skipped",IF(Settings!$B$15<>"Ready","Invalid settings",IF(OR(D22<>1,COUNTIF($A$2:$A$49,A22)<>1,NOT(ISNUMBER(E22)),E22<0,NOT(ISNUMBER(F22)),F22<0,F22>1),"Invalid input",IF(F22=1,"Complete",IF(OR(L22<=0,COUNTIFS($C$2:C21,C22,$M$2:M21,"Blocked*")+COUNTIFS($C$2:C21,C22,$M$2:M21,"Invalid*")>0,AND(G22<>"",OR(IFERROR(INDEX($D$2:$D$21,MATCH(G22,$A$2:$A$21,0)),0)<>1,IFERROR(INDEX($M$2:$M$21,MATCH(G22,$A$2:$A$21,0)),"Blocked")="Blocked",LEFT(IFERROR(INDEX($M$2:$M$21,MATCH(G22,$A$2:$A$21,0)),"Invalid"),7)="Invalid")),AND(H22<>"",OR(IFERROR(INDEX($D$2:$D$21,MATCH(H22,$A$2:$A$21,0)),0)<>1,IFERROR(INDEX($M$2:$M$21,MATCH(H22,$A$2:$A$21,0)),"Blocked")="Blocked",LEFT(IFERROR(INDEX($M$2:$M$21,MATCH(H22,$A$2:$A$21,0)),"Invalid"),7)="Invalid")),AND(I22<>"",OR(IFERROR(INDEX($D$2:$D$21,MATCH(I22,$A$2:$A$21,0)),0)<>1,IFERROR(INDEX($M$2:$M$21,MATCH(I22,$A$2:$A$21,0)),"Blocked")="Blocked",LEFT(IFERROR(INDEX($M$2:$M$21,MATCH(I22,$A$2:$A$21,0)),"Invalid"),7)="Invalid")),AND(J22<>"",OR(IFERROR(INDEX($D$2:$D$21,MATCH(J22,$A$2:$A$21,0)),0)<>1,IFERROR(INDEX($M$2:$M$21,MATCH(J22,$A$2:$A$21,0)),"Blocked")="Blocked",LEFT(IFERROR(INDEX($M$2:$M$21,MATCH(J22,$A$2:$A$21,0)),"Invalid"),7)="Invalid"))),"Blocked","Planned"))))) -> Planned | N22: =IF(M22="Skipped",O21,IF(OR(M22="Planned",M22="Complete"),MAX(O21,IF(G22="",0,IFERROR(INDEX($O$2:$O$21,MATCH(G22,$A$2:$A$21,0)),0)),IF(H22="",0,IFERROR(INDEX($O$2:$O$21,MATCH(H22,$A$2:$A$21,0)),0)),IF(I22="",0,IFERROR(INDEX($O$2:$O$21,MATCH(I22,$A$2:$A$21,0)),0)),IF(J22="",0,IFERROR(INDEX($O$2:$O$21,MATCH(J22,$A$2:$A$21,0)),0))),"")) -> 359.21569 | O22: =IF(M22="Skipped",N22,IF(OR(M22="Planned",M22="Complete"),N22+IF(K22=0,0,K22/L22),"")) -> 378.03922 | P22: =IF(AND(M22="Planned",K22>0),WORKDAY.INTL(Settings!$B$2-1,INT(N22+0.000000001)+1,Settings!$B$4,Holidays!$A$2:$A$101),"") -> 46737 | Q22: =IF(AND(M22="Planned",K22>0),WORKDAY.INTL(Settings!$B$2-1,MAX(1,ROUNDUP(O22-0.000000001,0)),Settings!$B$4,Holidays!$A$2:$A$101),"") -> 46759 | R22: =IF(OR(M22="Planned",M22="Complete"),O22-N22,0) -> 18.823529 | S22: Compare a fixed workflow and agent with budgets, stopping rules, and task evaluations. | T22: https://roadmap.sh/ai-agents
